Workbook

Sheet Sheet7
A1: Status | B1: Member | C1: Member | D1: Member
A2: Title | B2: Mr. | C2: Mr. | D2: Mrs.
A3: Last | B3: Okagbare | C3: Okagbare | D3: Okagbare
A4: First | B4: Prince | C4: Robert | D4: Voke
A5: Jan
A6: Dues-Jan | B6: 20 | D6: 20
A7: Feb
A8: Dues-Feb
A9: Mar
A10: Dues-Mar
A11: Apr
A12: Dues-Apr
A13: May
A14: Dues-May
A15: Jun
A16: Dues-Jun
A17: Jul
A18: Dues-Jul
... A28: Dues-Dec
A29: 2025 dues paid | B29: =SUM(B5:B28) -> 20 | C29: =SUM(C5:C28) -> 0 | D29: =SUM(D5:D28) -> 20
A30: 2025 balance | B30: =(B29 - (20* (MONTH(TODAY()) ))) -> -140 | C30: =(C29 - (20* (MONTH(TODAY()) ))) -> -160 | D30: =(D29 - (20* (MONTH(TODAY()) ))) -> -140
A31: 2024 balance | B31: 50 | C31: -20 | D31: 40
A32: 2023 balance | B32: 0 | C32: 0 | D32: 0
A33: 2022 balance | B33: 20 | C33: -120 | D33: 20
A34: 2021 balance2 | B34: -20 | C34: -20 | D34: -20
A35: 2020 balance | B35: -5 | C35: 220 | D35: 5
A36: 2019 balance | B36: -60 | C36: -200 | D36: -60
A37: 2018 balance | B37: -5 | C37: -120 | D37: -5
A38: Total | B38: =SUM(B30:B37) -> -160 | C38: =SUM(C30:C37) -> -420 | D38: =SUM(D30:D37) -> -160
A56: Donors | B56: Anambra Donation | C56: SSW Donation
A57: Dr. Emekpe | B57: 20 | C57: 50 | D57: 70
A58: Rouna Amege | B58: 20 | C58: 20 | D58: 40
A59: Minor Annete-Onoriode | B59: 20 | C59: 20 | D59: 40
A60: Emetiyoma Kwesi | B60: 20 | C60: 20 | D60: 40
A61: Okagbare Robert | B61: 50 | C61: 50 | D61: 50
A62: Mr. Emmanuel Orhorho | B62: 35 | C62: 35 | D62: 100
A63: Chief Godfrey Wanogho | B63: 20 | C63: 20 | D63: 40
A64: Prince & Voke Okagbare | B64: 40 | C64: 40 | D64: 80
A65: Benson Oghoufo | B65: 30 | C65: 30 | D65: 60
A66: Mr & Mrs Akaba | B66: 50 | C66: 20 | D66: 70
...

Sheet PivotTables
N1: Attendance | AF1: Hosting | AG1: Last | AH1: First | AI1: 2026 dues paid | AJ1: balance | AK1: Financial GoodStanding | AL1: Raffle tix UPUMI fundraiser | AM1: Raffle tix UPUA convention
AG2: Aguele | AH2: Sarah
AG3: Ngene | AH3: Abigail Enaibre | AI3: 190 | AJ3: 30 | AK3: Yes
AG4: Ngene | AH4: Jeff | AI4: 190 | AJ4: 30 | AK4: Yes
AG5: Orhorhoro | AH5: Odiri | AI5: 160 | AJ5: 80 | AK5: Yes
AG6: Ozorewor | AH6: Francis Onoriode | AI6: 180 | AJ6: 100 | AK6: Yes
AF7: 46023 | AG7: Ojugo | AH7: Christina | AI7: 80 | AJ7: 0 | AK7: Yes
AF8: 46023 | AG8: Onosode | AH8: Ochuko | AI8: 100 | AJ8: -80 | AK8: Yes | AL8: 50 | AM8: -20
AF9: 46023 | AG9: Onosode | AH9: Oghogho | AI9: 180 | AJ9: -80 | AK9: Yes | AL9: 50 | AM9: -20
AF10: 46054 | AG10: Ighofose | AH10: Ochuko | AI10: 50 | AJ10: -270 | AK10: No
AF11: 46054 | AG11: Ighofose | AH11: Sarah | AI11: 50 | AJ11: -270 | AK11: No
AF12: 46054 | AG12: Warrence | AH12: Julie | AI12: 240 | AJ12: 140 | AK12: Yes | AL12: 50 | AM12: 20
AF13: 46054 | AG13: Warrence | AH13: Paul | AI13: 240 | AJ13: 140 | AK13: Yes | AL13: 50 | AM13: 20
AF14: 46082 | AG14: Chiefredo | AH14: Merit | AI14: 167 | AJ14: 67 | AK14: Yes | AM14: 20
AF15: 46082 | AG15: Isiorho | AH15: Kehinde | AI15: 240 | AJ15: 80 | AK15: Yes | AL15: 50
AF16: 46082 | AG16: Obi | AH16: Rebecca | AI16: 240 | AJ16: 140 | AK16: Yes | AM16: 20
AF17: 46113 | AG17: Odjugo | AH17: Emuobonuvie | AI17: 0 | AJ17: -40 | AK17: Yes
AF18: 46113 | AG18: Odjugo | AH18: Julie | AI18: 0 | AJ18: -520 | AK18: No
AF19: 46113 | AG19: Orhorhoro | AH19: Daniel | AI19: 100 | AJ19: -140 | AK19: Yes | AM19: 20
AF20: 46113 | AG20: Orhorhoro | AH20: Florence | AI20: 100 | AJ20: -140 | AK20: Yes | AM20: 20
AF21: 46143 | AG21: Atori | AH21: Victoria | AI21: 0 | AJ21: -450 | AK21: No
AF22: 46143 | AG22: Emadamerho | AH22: Belief | AI22: 0 | AJ22: -340 | AK22: No
AF23: 46143 | AG23: Emadamerho | AH23: Krishawn | AI23: 0 | AJ23: -340 | AK23: No | AL23: 50
AF24: 46143 | AG24: Ikaji | AH24: Theresa | AI24: 0 | AJ24: -280 | AK24: No
AF25: 46174 | AG25: Evwaraye | AH25: Laura Adejoke | AI25: 0 | AJ25: -160 | AK25: Yes
AF26: 46174 | AG26: Evwaraye | AH26: Tive | AI26: 0 | AJ26: -160 | AK26: Yes
AF27: 46174 | AG27: George | AH27: Lovette | AI27: 170 | AJ27: -170 | AK27: Yes | AL27: 50 | AM27: 40
AF28: 46204 | AG28: Oleita | AH28: Jones | AI28: 240 | AJ28: -290 | AK28: No
AF29: 46204 | AG29: Oleita | AH29: Stella | AI29: 240 | AJ29: -290 | AK29: No
AF30: 46204 | AG30: Onokpikini | AH30: Eguono | AI30: 0 | AJ30: 0 | AK30: Yes
AF31: 46204 | AG31: Onokpikini | AH31: Kelvin | AI31: 0 | AJ31: 0 | AK31: Yes
AF32: 46266 | AG32: Okagbare | AH32: Onoerhime | AI32: 240 | AJ32: 500 | AK32: Yes | AL32: 50 | AM32: 20
AF33: 46266 | AG33: Okagbare | AH33: Prince | AI33: 240 | AJ33: 140 | AK33: Yes | AM33: 20
AF34: 46266 | AG34: Okagbare | AH34: Voke | AI34: 240 | AJ34: 140 | AK34: Yes | AM34: 20
AF35: 46296 | AG35: Akaba | AH35: Maureen | AI35: 120 | AJ35: -110 | AK35: Yes | AL35: 50
AF36: 46296 | AG36: Akaba | AH36: Monday | AI36: 120 | AJ36: -130 | AK36: Yes | AL36: 50
AF37: 46296 | AG37: Uduchukwu | AH37: Onagite | AI37: 0 | AJ37: -260 | AK37: No | AL37: - | AM37: -
AF38: 46296 | AG38: Uduchukwu | AH38: Tochukwu | AI38: 0 | AJ38: -260 | AK38: No | AL38: - | AM38: -
AF39: 46327 | AG39: Alawuru | AH39: Precious | AI39: 0 | AJ39: 90 | AK39: Yes
AF40: 46327 | AG40: Amegee | AH40: Ruona | AI40: 120 | AJ40: -40 | AK40: Yes | AL40: 50 | AM40: -20
...

Sheet Member_Status
A1: Status | B1: Title | C1: Last | D1: First | E1: Joined | F1: Phone2 | G1: Email | H1: Jan | I1: Dues-Jan | J1: Feb | K1: Dues-Feb | L1: Mar | M1: Dues-Mar | N1: Apr | O1: Dues-Apr | P1: May | Q1: Dues-May | R1: Jun | S1: Dues-Jun | T1: Jul | U1: Dues-Jul | V1: Aug | W1: Dues-Aug | X1: Sep | Y1: Dues-Sep | Z1: Oct | AA1: Dues-Oct | AB1: Nov | AC1: Dues-Nov | AD1: Dec | AE1: Dues-Dec | AF1: 2026 dues paid | AG1: 2026 balance | AH1: 2025 balance | AI1: 2024 balance | AJ1: 2023 balance | AK1: 2022 balance | AL1: 2021 balance2 | AM1: 2020 balance | AN1: 2019 balance | AO1: 2018 balance | AP1: Total | AQ1: Financial GoodStanding | AR1: %Attendance | AS1: Levies | AT1: Years active | AU1: GoodStanding | AV1: Voter | AW1: Insurance? | AX1: Ins. premium paid | AY1: Wrapper type | AZ1: Wrapper ordered | BA1: Wrapper payment | BB1: Hosting | BC1: Raffle tix UPUMI fundraiser | BD1: Raffle tix UPUA convention | BE1: SSW contribution | BF1: Anambra contribution | BG1: upua 25 raffle
A2: Member | B2: Mrs. | C2: Abada | D2: Evi | E2: 45130 | F2: (857) 248-8789 | H2: Present | O2: 120 | AF2: =SUM(H2:AE2) -> 120 | AG2: =(AF2 - (20* (MONTH(TODAY()) ))) -> -40 | AH2: -240 | AI2: 250 | AJ2: -10 | AK2: - | AL2: - | AM2: - | AN2: - | AO2: - | AP2: =SUM(AG2:AO2) -> -40 | AQ2: =IF((Member_Status!$AP2<-240), "No", "Yes") -> Yes | AR2: =COUNTIF(Member_Status!$H25:$AE25, "Present") / (MONTH(TODAY()-23 )) -> 0.28571429 | AS2: ='Bereavment Collection'!C2 -> 0 | AT2: =IF( (((TODAY() - E2) / 365) > 2), "2+", ((TODAY() - E2) / 365) ) -> 2+ | AU2: =IF( OR( (Member_Status!$AP25<-240), (Member_Status!$AS25<>0), (Member_Status!$AR25<58%) ), "No", "Yes") -> No | AV2: =IF( OR(Member_Status!$AQ2<>"Yes",AU2 <>"Yes" ), "No", "Yes" ) -> No | AW2: =IF( AND(AX2<149, OR(Member_Status!$AQ2<>"Yes", AT2<2 ) ), "No", "Yes" ) -> Yes | AY2: f | AZ2: 1 | BA2: 120 | BB2: 46447
A3: Member | B3: Mr. | C3: Abada | D3: Otuke | E3: 45047 | F3: 8576159120 | G3: abada351@gmail.com | H3: Present | O3: 120 | AF3: =SUM(H3:AE3) -> 120 | AG3: =(AF3 - (20* (MONTH(TODAY()) ))) -> -40 | AH3: -240 | AI3: 250 | AJ3: -10 | AK3: - | AL3: - | AM3: - | AN3: - | AO3: - | AP3: =SUM(AG3:AO3) -> -40 | AQ3: =IF((Member_Status!$AP3<-240), "No", "Yes") -> Yes | AR3: =COUNTIF(Member_Status!$H2:$AE2, "Present") / (MONTH(TODAY()-23 )) -> 0.14285714 | AS3: ='Bereavment Collection'!C3 -> 0 | AT3: =IF( (((TODAY() - E3) / 365) > 2), "2+", ((TODAY() - E3) / 365) ) -> 2+ | AU3: =IF( OR( (Member_Status!$AP2<-240), (Member_Status!$AS2<>0), (Member_Status!$AR2<58%) ), "No", "Yes") -> No | AV3: =IF( OR(Member_Status!$AQ3<>"Yes",AU3 <>"Yes" ), "No", "Yes" ) -> No | AW3: =IF( AND(AX3<149, OR(Member_Status!$AQ3<>"Yes", AT3<2 ) ), "No", "Yes" ) -> Yes | AY3: m | AZ3: 1 | BA3: 120 | BB3: 46447
A4: Member | B4: Mr. | C4: Agbara | D4: Onome | E4: 36892 | F4: 5862296613 | G4: vico08omolara@yahoo.com | P4: Present | Q4: 300 | AF4: =SUM(H4:AE4) -> 300 | AG4: =(AF4 - (20* (MONTH(TODAY()) ))) -> 140 | AH4: 80 | AI4: -240 | AJ4: 180 | AK4: -120 | AL4: -80 | AM4: -140 | AN4: - | AO4: - | AP4: =SUM(AG4:AO4) -> -180 | AQ4: =IF((Member_Status!$AP4<-240), "No", "Yes") -> Yes | AR4: =COUNTIF(Member_Status!$H3:$AE3, "Present") / (MONTH(TODAY()-23 )) -> 0.14285714 | AS4: ='Bereavment Collection'!C4 -> 0 | AT4: =IF( (((TODAY() - E4) / 365) > 2), "2+", ((TODAY() - E4) / 365) ) -> 2+ | AU4: =IF( OR( (Member_Status!$AP3<-240), (Member_Status!$AS3<>0), (Member_Status!$AR3<58%) ), "No", "Yes") -> No | AV4: =IF( OR(Member_Status!$AQ4<>"Yes",AU4 <>"Yes" ), "No", "Yes" ) -> No | AW4: =IF( AND(AX4<149, OR(Member_Status!$AQ4<>"Yes", AT4<2 ) ), "No", "Yes" ) -> Yes | AY4: m | BB4: - | BD4: 20
A5: Member | B5: Mr. | C5: Agbara | D5: Omolara | E5: 46081 | F5: 5863295145 | J5: Present | AF5: =SUM(H5:AE5) -> 0 | AG5: =(SUM(H5:AE5) - (20* (MONTH(TODAY()) ))+40) -> -120 | AP5: =SUM(AG5:AO5) -> -120 | AQ5: =IF((Member_Status!$AP5<-240), "No", "Yes") -> Yes | AR5: =COUNTIF(Member_Status!$H4:$AE4, "Present") / (MONTH(TODAY()-23 )) -> 0.14285714 | AS5: ='Bereavment Collection'!C5 -> 0 | AT5: =IF( (((TODAY() - E5) / 365) > 2), "2+", ((TODAY() - E5) / 365) ) -> 0.43287671 | AU5: =IF( OR( (Member_Status!$AP4<-240), (Member_Status!$AS4<>0), (Member_Status!$AR4<58%) ), "No", "Yes") -> No | AV5: =IF( OR(Member_Status!$AQ5<>"Yes",AU5 <>"Yes" ), "No", "Yes" ) -> No | AW5: =IF( AND(AX5<149, OR(Member_Status!$AQ5<>"Yes", AT5<2 ) ), "No", "Yes" ) -> No | AY5: f | BB5: New
A6: Member | B6: Mrs. | C6: Aguele | D6: Sarah | E6: 46143 | F6: 3134874212 | Q6: 200
A7: Member | B7: Mrs. | C7: Akaba | D7: Maureen | E7: 36894 | F7: 2482275923 | G7: =VLOOKUP(Member_Status!$D7,contacts!A:G,3,FALSE) -> #N/A | H7: Present | J7: Present | L7: Excused | M7: 120 | P7: Present | AF7: =SUM(H7:AE7) -> 120 | AG7: =(AF7 - (20* (MONTH(TODAY()) ))) -> -40 | AH7: 0 | AI7: 80 | AJ7: -60 | AK7: -90 | AL7: 0 | AM7: 0 | AN7: - | AO7: - | AP7: =SUM(AG7:AO7) -> -110 | AQ7: =IF((Member_Status!$AP7<-240), "No", "Yes") -> Yes | AR7: =COUNTIF(Member_Status!$H4:$AE4, "Present") / (MONTH(TODAY()-23 )) -> 0.14285714 | AS7: ='Bereavment Collection'!C5 -> 0 | AT7: =IF( (((TODAY() - E7) / 365) > 2), "2+", ((TODAY() - E7) / 365) ) -> 2+ | AU7: =IF( OR( (Member_Status!$AP4<-240), (Member_Status!$AS4<>0), (Member_Status!$AR4<58%) ), "No", "Yes") -> No | AV7: =IF( OR(Member_Status!$AQ7<>"Yes",AU7 <>"Yes" ), "No", "Yes" ) -> No | AW7: =IF( AND(AX7<149, OR(Member_Status!$AQ7<>"Yes", AT7<2 ) ), "No", "Yes" ) -> Yes | AY7: f | AZ7: 1 | BA7: 120 | BB7: 46296 | BC7: 50 | BE7: 20 | BF7: 50
A8: Member | B8: Mr. | C8: Akaba | D8: Monday | E8: 36893 | F8: 2482275923 | G8: =VLOOKUP(Member_Status!$D4,contacts!A:G,3,FALSE) -> onomeagbarha@hotmail.com | H8: Present | J8: Present | L8: Excused | M8: 120 | P8: Present | AF8: =SUM(H8:AE8) -> 120 | AG8: =(AF8 - (20* (MONTH(TODAY()) ))) -> -40 | AH8: 0 | AI8: 60 | AJ8: -60 | AK8: -90 | AL8: 0 | AM8: 0 | AN8: - | AO8: - | AP8: =SUM(AG8:AO8) -> -130 | AQ8: =IF((Member_Status!$AP8<-240), "No", "Yes") -> Yes | AR8: =COUNTIF(Member_Status!$H7:$AE7, "Present") / (MONTH(TODAY()-23 )) -> 0.42857143 | AS8: ='Bereavment Collection'!C6 -> 0 | AT8: =IF( (((TODAY() - E8) / 365) > 2), "2+", ((TODAY() - E8) / 365) ) -> 2+ | AU8: =IF( OR( (Member_Status!$AP7<-240), (Member_Status!$AS7<>0), (Member_Status!$AR7<58%) ), "No", "Yes") -> No | AV8: =IF( OR(Member_Status!$AQ8<>"Yes",AU8 <>"Yes" ), "No", "Yes" ) -> No | AW8: =IF( AND(AX8<149, OR(Member_Status!$AQ8<>"Yes", AT8<2 ) ), "No", "Yes" ) -> Yes | AY8: m | AZ8: 1 | BA8: 120 | BB8: 46296 | BC8: 50
A9: Member | B9: Mr. | C9: Akporee | D9: Emudiaga | E9: 45962 | F9: 7347262408 | G9: jformula123@gmail.com | Q9: 240 | AF9: =SUM(H9:AE9) -> 240 | AG9: =(AF9 - (40)) -> 200 | AH9: -240 | AI9: - | AJ9: - | AK9: - | AL9: - | AM9: - | AN9: - | AO9: - | AP9: =SUM(AG9:AO9) -> -40 | AQ9: =IF((Member_Status!$AP9<-240), "No", "Yes") -> Yes | AR9: =COUNTIF(Member_Status!$H8:$AE8, "Present") / (MONTH(TODAY()-23 )) -> 0.42857143 | AS9: ='Bereavment Collection'!C8 -> 0 | AT9: =IF( (((TODAY() - E9) / 365) > 2), "2+", ((TODAY() - E9) / 365) ) -> 0.75890411 | AU9: =IF( OR( (Member_Status!$AP8<-240), (Member_Status!$AS8<>0), (Member_Status!$AR8<58%) ), "No", "Yes") -> No | AV9: =IF( OR(Member_Status!$AQ9<>"Yes",AU9 <>"Yes" ), "No", "Yes" ) -> No | AW9: =IF( AND(AX9<149, OR(Member_Status!$AQ9<>"Yes", AT9<2 ) ), "No", "Yes" ) -> No | AY9: m | BB9: New | BC9: - | BD9: - | BE9: - | BF9: -
A10: Member | B10: Pastor | C10: Alawuru | D10: Precious | E10: 36895 | F10: 7342762638 | G10: =VLOOKUP(Member_Status!$D8,contacts!A:G,3,FALSE) -> mondaya@comcast.net | H10: Present | L10: Present | AF10: =SUM(H10:AE10) -> 0 | AG10: =(AF10 - (20* (MONTH(TODAY()) ))) -> -160 | AH10: -240 | AI10: 170 | AJ10: 0 | AK10: 0 | AL10: 0 | AM10: 320 | AN10: - | AO10: - | AP10: =SUM(AG10:AO10) -> 90 | AQ10: =IF((Member_Status!$AP10<-240), "No", "Yes") -> Yes | AR10: =COUNTIF(Member_Status!$H8:$AE8, "Present") / (MONTH(TODAY()-23 )) -> 0.42857143 | AS10: ='Bereavment Collection'!C8 -> 0 | AT10: =IF( (((TODAY() - E10) / 365) > 2), "2+", ((TODAY() - E10) / 365) ) -> 2+ | AU10: =IF( OR( (Member_Status!$AP8<-240), (Member_Status!$AS8<>0), (Member_Status!$AR8<58%) ), "No", "Yes") -> No | AV10: =IF( OR(Member_Status!$AQ10<>"Yes",AU10 <>"Yes" ), "No", "Yes" ) -> No | AW10: =IF( AND(AX10<149, OR(Member_Status!$AQ10<>"Yes", AT10<2 ) ), "No", "Yes" ) -> Yes | AY10: m | AZ10: 1 | BA10: 120 | BB10: 46327
A11: Member | B11: Mrs. | C11: Amegee | D11: Ruona | E11: 43770 | F11: 2487521535 | G11: =VLOOKUP(Member_Status!$D10,contacts!A:G,3,FALSE) -> palawuru@yahoo.com | H11: Present | I11: 20 | J11: Present | K11: 20 | L11: Excused | M11: 20 | O11: 20 | P11: Present | Q11: 20 | S11: 20 | U11: - | AF11: =SUM(H11:AE11) -> 120 | AG11: =(AF11 - (20* (MONTH(TODAY()) ))) -> -40 | AH11: 0 | AI11: 40 | AJ11: 0 | AK11: -20 | AL11: -20 | AM11: - | AN11: - | AO11: - | AP11: =SUM(AG11:AO11) -> -40 | AQ11: =IF((Member_Status!$AP11<-240), "No", "Yes") -> Yes | AR11: =COUNTIF(Member_Status!$H10:$AE10, "Present") / (MONTH(TODAY()-23 )) -> 0.28571429 | AS11: ='Bereavment Collection'!C9 -> -50 | AT11: =IF( (((TODAY() - E11) / 365) > 2), "2+", ((TODAY() - E11) / 365) ) -> 2+ | AU11: =IF( OR( (Member_Status!$AP10<-240), (Member_Status!$AS10<>0), (Member_Status!$AR10<58%) ), "No", "Yes") -> No | AV11: =IF( OR(Member_Status!$AQ11<>"Yes",AU11 <>"Yes" ), "No", "Yes" ) -> No | AW11: =IF( AND(AX11<149, OR(Member_Status!$AQ11<>"Yes", AT11<2 ) ), "No", "Yes" ) -> Yes | AY11: f | AZ11: 1 | BA11: 120 | BB11: 46327 | BC11: 50 | BD11: -20 | BE11: 20 | BF11: 20
A12: Member | B12: Ms. | C12: Asidi | D12: Fejiro | E12: 45597 | F12: 6185414024 | AF12: =SUM(H12:AE12) -> 0 | AG12: =(AF12 - (20* (MONTH(TODAY()) ))) -> -160 | AH12: -240 | AI12: -40 | AJ12: - | AK12: - | AL12: - | AM12: - | AN12: - | AO12: - | AP12: =SUM(AG12:AO12) -> -440 | AQ12: =IF((Member_Status!$AP12<-240), "No", "Yes") -> No | AR12: =COUNTIF(Member_Status!$H11:$AE11, "Present") / (MONTH(TODAY()-23 )) -> 0.42857143 | AS12: - | AT12: =IF( (((TODAY() - E12) / 365) > 2), "2+", ((TODAY() - E12) / 365) ) -> 1.7589041 | AU12: =IF( OR( (Member_Status!$AP11<-240), (Member_Status!$AS11<>0), (Member_Status!$AR11<58%) ), "No", "Yes") -> No | AV12: =IF( OR(Member_Status!$AQ12<>"Yes",AU12 <>"Yes" ), "No", "Yes" ) -> No | AW12: =IF( AND(AX12<149, OR(Member_Status!$AQ12<>"Yes", AT12<2 ) ), "No", "Yes" ) -> No | AY12: - | BB12: -
A13: Member | B13: Mrs. | C13: Atori | D13: Victoria | E13: 44287 | F13: 7345951092 | G13: =VLOOKUP(Member_Status!$D12,contacts!A:G,3,FALSE) -> #N/A | J13: Present | L13: Present | P13: Present | AF13: =SUM(H13:AE13) -> 0 | AG13: =(AF13 - (20* (MONTH(TODAY()) ))) -> -160 | AH13: -10 | AI13: -140 | AJ13: 100 | AK13: -240 | AL13: 0 | AM13: - | AN13: - | AO13: - | AP13: =SUM(AG13:AO13) -> -450 | AQ13: =IF((Member_Status!$AP13<-240), "No", "Yes") -> No | AR13: =COUNTIF(Member_Status!$H12:$AE12, "Present") / (MONTH(TODAY()-23 )) -> 0 | AS13: ='Bereavment Collection'!C11 -> -200 | AT13: =IF( (((TODAY() - E13) / 365) > 2), "2+", ((TODAY() - E13) / 365) ) -> 2+ | AU13: =IF( OR( (Member_Status!$AP12<-240), (Member_Status!$AS12<>0), (Member_Status!$AR12<58%) ), "No", "Yes") -> No | AV13: =IF( OR(Member_Status!$AQ13<>"Yes",AU13 <>"Yes" ), "No", "Yes" ) -> No | AW13: =IF( AND(AX13<149, OR(Member_Status!$AQ13<>"Yes", AT13<2 ) ), "No", "Yes" ) -> No | AY13: f | BB13: 46143
A14: Member | B14: Mrs. | C14: Chiefredo | D14: Merit | E14: 45658 | F14: 2487473278 | J14: Present | L14: Present | M14: 167 | P14: Present | AF14: =SUM(H14:AE14) -> 167 | AG14: =(AF14 - (20* (MONTH(TODAY()) ))) -> 7 | AH14: 0 | AI14: 0 | AJ14: 0 | AK14: -70 | AL14: 50 | AM14: 80 | AN14: - | AO14: 0 | AP14: =SUM(AG14:AO14) -> 67 | AQ14: =IF((Member_Status!$AP14<-240), "No", "Yes") -> Yes | AR14: =COUNTIF(Member_Status!$H74:$AE74, "Present") / (MONTH(TODAY()-23 )) -> 0.42857143 | AT14: =IF( (((TODAY() - E14) / 365) > 2), "2+", ((TODAY() - E14) / 365) ) -> 1.5917808 | AU14: =IF( OR( (Member_Status!$AP74<-240), (Member_Status!$AS74<>0), (Member_Status!$AR74<58%) ), "No", "Yes") -> No | AV14: =IF( OR(Member_Status!$AQ14<>"Yes",AU14 <>"Yes" ), "No", "Yes" ) -> No | AW14: =IF( AND(AX14<149, OR(Member_Status!$AQ14<>"Yes", AT14<2 ) ), "No", "Yes" ) -> Yes | AX14: 153 | AY14: f | AZ14: 1 | BA14: 300 | BB14: 46082 | BD14: 20 | BG14: 20
A15: Member | B15: Mrs. | C15: Dilworth | D15: Aghogho | E15: 44398 | F15: 3135302348 | G15: =VLOOKUP(Member_Status!$D13,contacts!A:G,3,FALSE) -> #N/A | H15: Present | J15: Present | K15: 200 | L15: Present | P15: Present | AF15: =SUM(H15:AE15) -> 200 | AG15: =(AF15 - (20* (MONTH(TODAY()) ))) -> 40 | AH15: 0 | AI15: -140 | AJ15: 0 | AK15: 0 | AL15: -40 | AM15: - | AN15: - | AO15: - | AP15: =SUM(AG15:AO15) -> -140 | AQ15: =IF((Member_Status!$AP15<-240), "No", "Yes") -> Yes | AR15: =COUNTIF(Member_Status!$H13:$AE13, "Present") / (MONTH(TODAY()-23 )) -> 0.42857143 | AS15: ='Bereavment Collection'!C13 -> 0 | AT15: =IF( (((TODAY() - E15) / 365) > 2), "2+", ((TODAY() - E15) / 365) ) -> 2+ | AU15: =IF( OR( (Member_Status!$AP13<-240), (Member_Status!$AS13<>0), (Member_Status!$AR13<58%) ), "No", "Yes") -> No | AV15: =IF( OR(Member_Status!$AQ15<>"Yes",AU15 <>"Yes" ), "No", "Yes" ) -> No | AW15: =IF( AND(AX15<149, OR(Member_Status!$AQ15<>"Yes", AT15<2 ) ), "No", "Yes" ) -> Yes | AY15: f | AZ15: 1 | BA15: 120 | BB15: 46327 | BC15: 50 | BD15: -20 | BF15: 20
A16: Member | B16: Mrs. | C16: Eghwofobe | D16: Ngozi | E16: 36892 | F16: 2482527976 | G16: =LOOKUP(Member_Status!$D14,contacts!A:A,contacts!C:C) -> meanvipro@yahoo.com | H16: Present | O16: 240 | P16: Present | AF16: =SUM(H16:AE16) -> 240 | AG16: =(AF16 - (20* (MONTH(TODAY()) ))) -> 80 | AH16: 0 | AI16: 0 | AJ16: 0 | AK16: 0 | AL16: 0 | AM16: -60 | AN16: 120 | AO16: 40 | AP16: =SUM(AG16:AO16) -> 180 | AQ16: =IF((Member_Status!$AP16<-240), "No", "Yes") -> Yes | AR16: =COUNTIF(Member_Status!$H14:$AE14, "Present") / (MONTH(TODAY()-23 )) -> 0.42857143 | AS16: ='Bereavment Collection'!C14 -> -50 | AT16: =IF( (((TODAY() - E16) / 365) > 2), "2+", ((TODAY() - E16) / 365) ) -> 2+ | AU16: =IF( OR( (Member_Status!$AP14<-240), (Member_Status!$AS14<>0), (Member_Status!$AR14<58%) ), "No", "Yes") -> No | AV16: =IF( OR(Member_Status!$AQ16<>"Yes",AU16 <>"Yes" ), "No", "Yes" ) -> No | AW16: =IF( AND(AX16<149, OR(Member_Status!$AQ16<>"Yes", AT16<2 ) ), "No", "Yes" ) -> Yes | AY16: f | AZ16: 1 | BA16: 120 | BB16: 46327 | BC16: 50 | BD16: 20
A17: Member | B17: Mr. | C17: Ejafiavwo | D17: Robinson | E17: 43709 | F17: 7344449859 | G17: =VLOOKUP(#REF!,contacts!A:G,3,FALSE) -> #REF! | AF17: =SUM(H17:AE17) -> 0 | AG17: =(AF17 - (20* (MONTH(TODAY()) ))) -> -160 | AH17: -240 | AI17: 240 | AJ17: -240 | AK17: 0 | AL17: 0 | AM17: -120 | AN17: 0 | AO17: - | AP17: =SUM(AG17:AO17) -> -520 | AQ17: =IF((Member_Status!$AP17<-240), "No", "Yes") -> No | AR17: =COUNTIF(Member_Status!$H15:$AE15, "Present") / (MONTH(TODAY()-23 )) -> 0.57142857 | AS17: ='Bereavment Collection'!C16 -> 0 | AT17: =IF( (((TODAY() - E17) / 365) > 2), "2+", ((TODAY() - E17) / 365) ) -> 2+ | AU17: =IF( OR( (Member_Status!$AP15<-240), (Member_Status!$AS15<>0), (Member_Status!$AR15<58%) ), "No", "Yes") -> No | AV17: =IF( OR(Member_Status!$AQ17<>"Yes",AU17 <>"Yes" ), "No", "Yes" ) -> No | AW17: =IF( AND(AX17<149, OR(Member_Status!$AQ17<>"Yes", AT17<2 ) ), "No", "Yes" ) -> No | AY17: m | BB17: 46388
A18: Member | B18: Mr. | C18: Emadamerho | D18: Krishawn | E18: 43497 | F18: 2485210669 | G18: =VLOOKUP(Member_Status!$D16,contacts!A:G,3,FALSE) -> reghwofobe@peoplepc.com | L18: Excused | P18: Present | AF18: =SUM(H18:AE18) -> 0 | AG18: =(AF18 - (20* (MONTH(TODAY()) ))) -> -160 | AH18: -10 | AI18: -30 | AJ18: 100 | AK18: -240 | AL18: 0 | AM18: 0 | AN18: - | AO18: - | AP18: =SUM(AG18:AO18) -> -340 | AQ18: =IF((Member_Status!$AP18<-240), "No", "Yes") -> No | AR18: =COUNTIF(Member_Status!$H17:$AE17, "Present") / (MONTH(TODAY()-23 )) -> 0 | AS18: ='Bereavment Collection'!C18 -> -50 | AT18: =IF( (((TODAY() - E18) / 365) > 2), "2+", ((TODAY() - E18) / 365) ) -> 2+ | AU18: =IF( OR( (Member_Status!$AP17<-240), (Member_Status!$AS17<>0), (Member_Status!$AR17<58%) ), "No", "Yes") -> No | AV18: =IF( OR(Member_Status!$AQ18<>"Yes",AU18 <>"Yes" ), "No", "Yes" ) -> No | AW18: =IF( AND(AX18<149, OR(Member_Status!$AQ18<>"Yes", AT18<2 ) ), "No", "Yes" ) -> No | AY18: f | BA18: 120 | BB18: 46143 | BC18: 50
A19: Member | B19: Mr. | C19: Emadamerho | D19: Belief | E19: 36892 | F19: 3132181786 | G19: =VLOOKUP(Member_Status!$D17,contacts!A:G,3,FALSE) -> ejefia@hotmail.com | H19: Present | L19: Present | P19: Present | AF19: =SUM(H19:AE19) -> 0 | AG19: =(AF19 - (20* (MONTH(TODAY()) ))) -> -160 | AH19: -10 | AI19: -30 | AJ19: 100 | AK19: -240 | AL19: 0 | AM19: 0 | AN19: 0 | AO19: 0 | AP19: =SUM(AG19:AO19) -> -340 | AQ19: =IF((Member_Status!$AP19<-240), "No", "Yes") -> No | AR19: =COUNTIF(Member_Status!$H16:$AE16, "Present") / (MONTH(TODAY()-23 )) -> 0.28571429 | AS19: ='Bereavment Collection'!C17 -> 0 | AT19: =IF( (((TODAY() - E19) / 365) > 2), "2+", ((TODAY() - E19) / 365) ) -> 2+ | AU19: =IF( OR( (Member_Status!$AP16<-240), (Member_Status!$AS16<>0), (Member_Status!$AR16<58%) ), "No", "Yes") -> No | AV19: =IF( OR(Member_Status!$AQ19<>"Yes",AU19 <>"Yes" ), "No", "Yes" ) -> No | AW19: =IF( AND(AX19<149, OR(Member_Status!$AQ19<>"Yes", AT19<2 ) ), "No", "Yes" ) -> No | AY19: m | BA19: 120 | BB19: 46143
A20: Member | B20: Mrs. | C20: Emekpe | D20: Enovwo | E20: 43770 | F20: 2488852808 | G20: =VLOOKUP(Member_Status!$D18,contacts!A:G,3,FALSE) -> #N/A | L20: Present | M20: 270 | AF20: =SUM(H20:AE20) -> 270 | AG20: =(AF20 - (20* (MONTH(TODAY()) ))) -> 110 | AH20: -80 | AI20: -130 | AJ20: 0 | AK20: 0 | AL20: 0 | AM20: 0 | AN20: - | AO20: - | AP20: =SUM(AG20:AO20) -> -100 | AQ20: =IF((Member_Status!$AP20<-240), "No", "Yes") -> Yes | AR20: =COUNTIF(Member_Status!$H18:$AE18, "Present") / (MONTH(TODAY()-23 )) -> 0.14285714 | AS20: ='Bereavment Collection'!C19 -> 0 | AT20: =IF( (((TODAY() - E20) / 365) > 2), "2+", ((TODAY() - E20) / 365) ) -> 2+ | AU20: =IF( OR( (Member_Status!$AP18<-240), (Member_Status!$AS18<>0), (Member_Status!$AR18<58%) ), "No", "Yes") -> No | AV20: =IF( OR(Member_Status!$AQ20<>"Yes",AU20 <>"Yes" ), "No", "Yes" ) -> No | AW20: =IF( AND(AX20<149, OR(Member_Status!$AQ20<>"Yes", AT20<2 ) ), "No", "Yes" ) -> Yes | AY20: f | AZ20: 1 | BA20: 120 | BB20: 46478 | BC20: 50 | BD20: 20 | BE20: 50 | BF20: 20
A21: Member | B21: Mr. | C21: Emetiyoma | D21: Kwesi | E21: 45078 | F21: (248) 766-3000 | H21: Present | J21: Present | L21: Present | P21: Present | Q21: - | S21: 100 | U21: - | AF21: =SUM(H21:AE21) -> 100 | AG21: =(AF21 - (20* (MONTH(TODAY()) ))) -> -60 | AH21: -140 | AI21: -10 | AJ21: -10 | AK21: - | AL21: - | AM21: - | AN21: - | AO21: - | AP21: =SUM(AG21:AO21) -> -220 | AQ21: =IF((Member_Status!$AP21<-240), "No", "Yes") -> Yes | AR21: =COUNTIF(Member_Status!$H19:$AE19, "Present") / (MONTH(TODAY()-23 )) -> 0.42857143 | AS21: ='Bereavment Collection'!C24 -> 0 | AT21: =IF( (((TODAY() - E21) / 365) > 2), "2+", ((TODAY() - E21) / 365) ) -> 2+ | AU21: =IF( OR( (Member_Status!$AP19<-240), (Member_Status!$AS19<>0), (Member_Status!$AR19<58%) ), "No", "Yes") -> No | AV21: =IF( OR(Member_Status!$AQ21<>"Yes",AU21 <>"Yes" ), "No", "Yes" ) -> No | AW21: =IF( AND(AX21<149, OR(Member_Status!$AQ21<>"Yes", AT21<2 ) ), "No", "Yes" ) -> Yes | AY21: f | AZ21: 1 | BA21: 120 | BB21: 46419 | BD21: -20 | BE21: 20 | BF21: 20
A22: Member | B22: Mr. | C22: Eruoto | D22: Jude | E22: 45627 | F22: 9062039273 | H22: Present | AF22: =SUM(H22:AE22) -> 0 | AG22: =(AF22 - (20* (MONTH(TODAY()) ))) -> -160 | AH22: -240 | AI22: 0 | AJ22: - | AK22: - | AL22: - | AM22: - | AN22: - | AO22: - | AP22: =SUM(AG22:AO22) -> -400 | AQ22: =IF((Member_Status!$AP22<-240), "No", "Yes") -> No | AR22: =COUNTIF(Member_Status!$H20:$AE20, "Present") / (MONTH(TODAY()-23 )) -> 0.14285714 | AS22: ='Bereavment Collection'!C25 -> 0 | AT22: =IF( (((TODAY() - E22) / 365) > 2), "2+", ((TODAY() - E22) / 365) ) -> 1.6767123 | AU22: =IF( OR( (Member_Status!$AP20<-240), (Member_Status!$AS20<>0), (Member_Status!$AR20<58%) ), "No", "Yes") -> No | AV22: =IF( OR(Member_Status!$AQ22<>"Yes",AU22 <>"Yes" ), "No", "Yes" ) -> No | AW22: =IF( AND(AX22<149, OR(Member_Status!$AQ22<>"Yes", AT22<2 ) ), "No", "Yes" ) -> No | AY22: m | BB22: -
A23: Member | B23: Mr. | C23: Esegine | D23: Johnson | E23: 36892 | F23: 2485048066 | G23: =VLOOKUP(Member_Status!$D21,contacts!A:G,3,FALSE) -> meanvipro@yahoo.com | I23: 90 | M23: 50 | AF23: =SUM(H23:AE23) -> 140 | AG23: =(AF23 - (10* (MONTH(TODAY()) ))) -> 60 | AH23: 20 | AI23: -20 | AJ23: 20 | AK23: -100 | AL23: -60 | AM23: -40 | AN23: - | AO23: - | AP23: =SUM(AG23:AO23) -> -120 | AQ23: =IF((Member_Status!$AP23<-120), "No", "Yes") -> Yes | AR23: =COUNTIF(Member_Status!$H21:$AE21, "Present") / (MONTH(TODAY()-23 )) -> 0.57142857 | AS23: ='Bereavment Collection'!C20 -> -50 | AT23: =IF( (((TODAY() - E23) / 365) > 2), "2+", ((TODAY() - E23) / 365) ) -> 2+ | AU23: =IF( OR( (Member_Status!$AP21<-120), (Member_Status!$AS21<>0), (Member_Status!$AR21<58%) ), "No", "Yes") -> No | AV23: =IF( OR(Member_Status!$AQ23<>"Yes",AU23 <>"Yes" ), "No", "Yes" ) -> No | AW23: =IF( AND(AX23<149, OR(Member_Status!$AQ23<>"Yes", AT23<2 ) ), "No", "Yes" ) -> Yes | AY23: m | BB23: elder | BC23: -
A24: Member | B24: Mrs. | C24: Esegine | D24: Rebecca | E24: 36892 | F24: 2489125998 | G24: =VLOOKUP(Member_Status!$D22,contacts!A:G,3,FALSE) -> #N/A | I24: 90 | M24: 50 | AF24: =SUM(H24:AE24) -> 140 | AG24: =(AF24 - (10* (MONTH(TODAY()) ))) -> 60 | AH24: 20 | AI24: -20 | AJ24: 20 | AK24: -100 | AL24: -60 | AM24: -40 | AN24: - | AO24: - | AP24: =SUM(AG24:AO24) -> -120 | AQ24: =IF((Member_Status!$AP24<-120), "No", "Yes") -> Yes | AR24: =COUNTIF(Member_Status!$H22:$AE22, "Present") / (MONTH(TODAY()-23 )) -> 0.14285714 | AS24: ='Bereavment Collection'!C21 -> -50 | AT24: =IF( (((TODAY() - E24) / 365) > 2), "2+", ((TODAY() - E24) / 365) ) -> 2+ | AU24: =IF( OR( (Member_Status!$AP22<-120), (Member_Status!$AS22<>0), (Member_Status!$AR22<58%) ), "No", "Yes") -> No | AV24: =IF( OR(Member_Status!$AQ24<>"Yes",AU24 <>"Yes" ), "No", "Yes" ) -> No | AW24: =IF( AND(AX24<149, OR(Member_Status!$AQ24<>"Yes", AT24<2 ) ), "No", "Yes" ) -> Yes | AY24: f | BB24: elder | BC24: -
A25: Member | B25: Mrs. | C25: Evwaraye | D25: Laura Adejoke | E25: 45346 | F25: 810 4105267 | G25: lae4766@gmail.com | J25: Present | P25: Present | AF25: =SUM(H25:AE25) -> 0 | AG25: =(AF25 - (20* (MONTH(TODAY()) ))) -> -160 | AH25: 0 | AI25: 0 | AJ25: - | AK25: - | AL25: - | AM25: - | AN25: - | AO25: - | AP25: =SUM(AG25:AO25) -> -160 | AQ25: =IF((Member_Status!$AP25<-240), "No", "Yes") -> Yes | AR25: =COUNTIF(Member_Status!$H23:$AE23, "Present") / (MONTH(TODAY()-23 )) -> 0 | AS25: ='Bereavment Collection'!C22 -> 0 | AT25: =IF( (((TODAY() - E25) / 365) > 2), "2+", ((TODAY() - E25) / 365) ) -> 2+ | AU25: =IF( OR( (Member_Status!$AP23<-240), (Member_Status!$AS23<>0), (Member_Status!$AR23<58%) ), "No", "Yes") -> No | AV25: =IF( OR(Member_Status!$AQ25<>"Yes",AU25 <>"Yes" ), "No", "Yes" ) -> No | AW25: =IF( AND(AX25<149, OR(Member_Status!$AQ25<>"Yes", AT25<2 ) ), "No", "Yes" ) -> Yes | AY25: f | AZ25: 2 | BA25: 240 | BB25: 46174
A26: Member | B26: Mr. | C26: Evwaraye | D26: Tive | E26: 45347 | F26: 313 6900667 | G26: Te2675@yahoo.com | J26: Present | L26: Present | P26: Present | AF26: =SUM(H26:AE26) -> 0 | AG26: =(AF26 - (20* (MONTH(TODAY()) ))) -> -160 | AH26: 0 | AI26: 0 | AJ26: - | AK26: - | AL26: - | AM26: - | AN26: - | AO26: - | AP26: =SUM(AG26:AO26) -> -160 | AQ26: =IF((Member_Status!$AP26<-240), "No", "Yes") -> Yes | AR26: =COUNTIF(Member_Status!$H24:$AE24, "Present") / (MONTH(TODAY()-23 )) -> 0 | AS26: ='Bereavment Collection'!C23 -> 0 | AT26: =IF( (((TODAY() - E26) / 365) > 2), "2+", ((TODAY() - E26) / 365) ) -> 2+ | AU26: =IF( OR( (Member_Status!$AP24<-240), (Member_Status!$AS24<>0), (Member_Status!$AR24<58%) ), "No", "Yes") -> No | AV26: =IF( OR(Member_Status!$AQ26<>"Yes",AU26 <>"Yes" ), "No", "Yes" ) -> No | AW26: =IF( AND(AX26<149, OR(Member_Status!$AQ26<>"Yes", AT26<2 ) ), "No", "Yes" ) -> Yes | AY26: f | BB26: 46174 | BE26: 20 | BF26: 20
A27: Member | B27: Mrs. | C27: George | D27: Lovette | E27: 45227 | F27: (248)736 7156. | G27: lovette_george@yahoo.com | H27: Present | J27: Present | M27: 40 | O27: 130 | P27: Present | AF27: =SUM(H27:AE27) -> 170 | AG27: =(AF27 - (20* (MONTH(TODAY()) ))) -> 10 | AH27: -200 | AI27: -20 | AJ27: 40 | AK27: - | AL27: - | AM27: - | AN27: - | AO27: - | AP27: =SUM(AG27:AO27) -> -170 | AQ27: =IF((Member_Status!$AP27<-240), "No", "Yes") -> Yes | AR27: =COUNTIF(Member_Status!$H26:$AE26, "Present") / (MONTH(TODAY()-23 )) -> 0.42857143 | AS27: ='Bereavment Collection'!C26 -> 0 | AT27: =IF( (((TODAY() - E27) / 365) > 2), "2+", ((TODAY() - E27) / 365) ) -> 2+ | AU27: =IF( OR( (Member_Status!$AP26<-240), (Member_Status!$AS26<>0), (Member_Status!$AR26<58%) ), "No", "Yes") -> No | AV27: =IF( OR(Member_Status!$AQ27<>"Yes",AU27 <>"Yes" ), "No", "Yes" ) -> No | AW27: =IF( AND(AX27<149, OR(Member_Status!$AQ27<>"Yes", AT27<2 ) ), "No", "Yes" ) -> Yes | AY27: f | AZ27: 1 | BA27: 120 | BB27: 46174 | BC27: 50 | BD27: 40
A28: Member | B28: Mr. | C28: Ighofose | D28: Ochuko | E28: 45008 | F28: (313) 529-0205 | J28: Present | K28: 50 | L28: Excused | P28: Present | AF28: =SUM(H28:AE28) -> 50 | AG28: =(AF28 - (20* (MONTH(TODAY()) ))) -> -110 | AH28: -160 | AI28: 40 | AJ28: -40 | AK28: - | AL28: - | AM28: - | AN28: - | AO28: - | AP28: =SUM(AG28:AO28) -> -270 | AQ28: =IF((Member_Status!$AP28<-240), "No", "Yes") -> No | AR28: =COUNTIF(Member_Status!$H27:$AE27, "Present") / (MONTH(TODAY()-23 )) -> 0.42857143 | AS28: ='Bereavment Collection'!C27 -> 0 | AT28: =IF( (((TODAY() - E28) / 365) > 2), "2+", ((TODAY() - E28) / 365) ) -> 2+ | AU28: =IF( OR( (Member_Status!$AP27<-240), (Member_Status!$AS27<>0), (Member_Status!$AR27<58%) ), "No", "Yes") -> No | AV28: =IF( OR(Member_Status!$AQ28<>"Yes",AU28 <>"Yes" ), "No", "Yes" ) -> No | AW28: =IF( AND(AX28<149, OR(Member_Status!$AQ28<>"Yes", AT28<2 ) ), "No", "Yes" ) -> No | AY28: m | AZ28: 1 | BA28: 120 | BB28: 46054
A29: Member | B29: Mrs. | C29: Ighofose | D29: Sarah | E29: 45008 | F29: (313) 487-4212 | J29: Present | K29: 50 | L29: Present | P29: Present | AF29: =SUM(H29:AE29) -> 50 | AG29: =(AF29 - (20* (MONTH(TODAY()) ))) -> -110 | AH29: -160 | AI29: 40 | AJ29: -40 | AK29: - | AL29: - | AM29: - | AN29: - | AO29: - | AP29: =SUM(AG29:AO29) -> -270 | AQ29: =IF((Member_Status!$AP29<-240), "No", "Yes") -> No | AR29: =COUNTIF(Member_Status!$H28:$AE28, "Present") / (MONTH(TODAY()-23 )) -> 0.28571429 | AS29: ='Bereavment Collection'!C28 -> 0 | AT29: =IF( (((TODAY() - E29) / 365) > 2), "2+", ((TODAY() - E29) / 365) ) -> 2+ | AU29: =IF( OR( (Member_Status!$AP28<-240), (Member_Status!$AS28<>0), (Member_Status!$AR28<58%) ), "No", "Yes") -> No | AV29: =IF( OR(Member_Status!$AQ29<>"Yes",AU29 <>"Yes" ), "No", "Yes" ) -> No | AW29: =IF( AND(AX29<149, OR(Member_Status!$AQ29<>"Yes", AT29<2 ) ), "No", "Yes" ) -> No | AY29: f | AZ29: 1 | BA29: 120 | BB29: 46054
A30: Member | B30: Mrs. | C30: Ikaji | D30: Theresa | E30: 36892 | F30: 3132581826 | G30: =VLOOKUP(Member_Status!$D29,contacts!A:G,3,FALSE) -> #N/A | L30: Present | P30: Present | AF30: =SUM(H30:AE30) -> 0 | AG30: =(AF30 - (20* (MONTH(TODAY()) ))) -> -160 | AH30: 20 | AI30: 100 | AJ30: 0 | AK30: -240 | AL30: 0 | AM30: - | AN30: - | AO30: - | AP30: =SUM(AG30:AO30) -> -280 | AQ30: =IF((Member_Status!$AP30<-240), "No", "Yes") -> No | AR30: =COUNTIF(Member_Status!$H29:$AE29, "Present") / (MONTH(TODAY()-23 )) -> 0.42857143 | AS30: ='Bereavment Collection'!C29 -> -200 | AT30: =IF( (((TODAY() - E30) / 365) > 2), "2+", ((TODAY() - E30) / 365) ) -> 2+ | AU30: =IF( OR( (Member_Status!$AP29<-240), (Member_Status!$AS29<>0), (Member_Status!$AR29<58%) ), "No", "Yes") -> No | AV30: =IF( OR(Member_Status!$AQ30<>"Yes",AU30 <>"Yes" ), "No", "Yes" ) -> No | AW30: =IF( AND(AX30<149, OR(Member_Status!$AQ30<>"Yes", AT30<2 ) ), "No", "Yes" ) -> No | AY30: f | BB30: 46143
A31: Member | B31: Mrs. | C31: Isiorho | D31: Kehinde | E31: 44652 | F31: 13462821181 | J31: Present | L31: Present | M31: 120 | Q31: - | S31: 120 | U31: - | AF31: =SUM(H31:AE31) -> 240 | AG31: =(AF31 - (20* (MONTH(TODAY()) ))) -> 80 | AH31: -20 | AI31: 20 | AJ31: 0 | AK31: 0 | AL31: - | AM31: - | AN31: - | AO31: - | AP31: =SUM(AG31:AO31) -> 80 | AQ31: =IF((Member_Status!$AP31<-240), "No", "Yes") -> Yes | AR31: =COUNTIF(Member_Status!$H30:$AE30, "Present") / (MONTH(TODAY()-23 )) -> 0.28571429 | AS31: ='Bereavment Collection'!C30 -> -50 | AT31: =IF( (((TODAY() - E31) / 365) > 2), "2+", ((TODAY() - E31) / 365) ) -> 2+ | AU31: =IF( OR( (Member_Status!$AP30<-240), (Member_Status!$AS30<>0), (Member_Status!$AR30<58%) ), "No", "Yes") -> No | AV31: =IF( OR(Member_Status!$AQ31<>"Yes",AU31 <>"Yes" ), "No", "Yes" ) -> No | AW31: =IF( AND(AX31<149, OR(Member_Status!$AQ31<>"Yes", AT31<2 ) ), "No", "Yes" ) -> Yes | AY31: f | AZ31: 1 | BA31: 120 | BB31: 46082 | BC31: 50 | BF31: 20
A32: Member | B32: Mrs. | C32: Minor | D32: Annete-Onoriode | E32: 36892 | F32: 2487471200 | G32: =VLOOKUP(Member_Status!$D31,contacts!A:G,3,FALSE) -> #N/A | L32: Present | M32: 240 | AF32: =SUM(H32:AE32) -> 240 | AG32: =(AF32 - (20* (MONTH(TODAY()) ))) -> 80 | AH32: 0 | AI32: 0 | AJ32: -240 | AK32: 240 | AL32: 0 | AM32: 0 | AN32: 0 | AO32: 0 | AP32: =SUM(AG32:AO32) -> 80 | AQ32: =IF((Member_Status!$AP32<-240), "No", "Yes") -> Yes | AR32: =COUNTIF(Member_Status!$H31:$AE31, "Present") / (MONTH(TODAY()-23 )) -> 0.28571429 | AS32: ='Bereavment Collection'!C31 -> 0 | AT32: =IF( (((TODAY() - E32) / 365) > 2), "2+", ((TODAY() - E32) / 365) ) -> 2+ | AU32: =IF( OR( (Member_Status!$AP31<-240), (Member_Status!$AS31<>0), (Member_Status!$AR31<58%) ), "No", "Yes") -> No | AV32: =IF( OR(Member_Status!$AQ32<>"Yes",AU32 <>"Yes" ), "No", "Yes" ) -> No | AW32: =IF( AND(AX32<149, OR(Member_Status!$AQ32<>"Yes", AT32<2 ) ), "No", "Yes" ) -> Yes | AY32: f | AZ32: 1 | BA32: 120 | BB32: 46478 | BC32: 50 | BD32: 20 | BE32: 20 | BF32: 20
A33: Member | B33: Dr. | C33: Nana | D33: Edewor | E33: 36892 | F33: 2487471200 | G33: tubitaki@aol.com | H33: Present | J33: Present | L33: Present | M33: 240 | P33: Present | AF33: =SUM(H33:AE33) -> 240 | AG33: =(AF33 - (20* (MONTH(TODAY()) ))) -> 80 | AH33: 0 | AI33: 0 | AJ33: 0 | AK33: 0 | AL33: 0 | AM33: 0 | AN33: 0 | AO33: 0 | AP33: =SUM(AG33:AO33) -> 80 | AQ33: =IF((Member_Status!$AP33<-240), "No", "Yes") -> Yes | AR33: =COUNTIF(Member_Status!$H32:$AE32, "Present") / (MONTH(TODAY()-23 )) -> 0.14285714 | AS33: ='Bereavment Collection'!C32 -> 0 | AT33: =IF( (((TODAY() - E33) / 365) > 2), "2+", ((TODAY() - E33) / 365) ) -> 2+ | AU33: =IF( OR( (Member_Status!$AP32<-240), (Member_Status!$AS32<>0), (Member_Status!$AR32<58%) ), "No", "Yes") -> No | AV33: =IF( OR(Member_Status!$AQ33<>"Yes",AU33 <>"Yes" ), "No", "Yes" ) -> No | AW33: =IF( AND(AX33<149, OR(Member_Status!$AQ33<>"Yes", AT33<2 ) ), "No", "Yes" ) -> Yes | AY33: m | BB33: 46419 | BC33: 50 | BD33: 20
A34: Member | B34: Mrs. | C34: Nana | D34: Tessy | E34: 36892 | F34: 2486672255 | G34: =VLOOKUP(Member_Status!$D33,contacts!A:G,3,FALSE) -> #N/A | H34: Present | J34: Excused | L34: Excused | M34: 240 | AF34: =SUM(H34:AE34) -> 240 | AG34: =(AF34 - (20* (MONTH(TODAY()) ))) -> 80 | AH34: 0 | AI34: 0 | AJ34: 0 | AK34: 0 | AL34: 0 | AM34: 0 | AN34: 0 | AO34: 0 | AP34: =SUM(AG34:AO34) -> 80 | AQ34: =IF((Member_Status!$AP34<-240), "No", "Yes") -> Yes | AR34: =COUNTIF(Member_Status!$H33:$AE33, "Present") / (MONTH(TODAY()-23 )) -> 0.57142857 | AS34: ='Bereavment Collection'!C33 -> 0 | AT34: =IF( (((TODAY() - E34) / 365) > 2), "2+", ((TODAY() - E34) / 365) ) -> 2+ | AU34: =IF( OR( (Member_Status!$AP33<-240), (Member_Status!$AS33<>0), (Member_Status!$AR33<58%) ), "No", "Yes") -> No | AV34: =IF( OR(Member_Status!$AQ34<>"Yes",AU34 <>"Yes" ), "No", "Yes" ) -> No | AW34: =IF( AND(AX34<149, OR(Member_Status!$AQ34<>"Yes", AT34<2 ) ), "No", "Yes" ) -> Yes | AY34: f | AZ34: 2 | BA34: 240 | BB34: 46419 | BC34: 50 | BD34: 20
A35: Member | B35: Mr. | C35: Ngene | D35: Jeff | E35: 46113 | F35: 3135566202 | O35: =380/2 -> 190 | AF35: =SUM(H35:AE35) -> 190 | AG35: =(AF35 - (20* (MONTH(TODAY()) ))) -> 30 | AH35: - | AI35: - | AJ35: - | AK35: - | AL35: - | AM35: - | AN35: - | AO35: - | AP35: =SUM(AG35:AO35) -> 30 | AQ35: =IF((Member_Status!$AP35<-240), "No", "Yes") -> Yes | AR35: =COUNTIF(Member_Status!$H34:$AE34, "Present") / (MONTH(TODAY()-23 )) -> 0.14285714 | AS35: ='Bereavment Collection'!C34 -> 0 | AT35: =IF( (((TODAY() - E35) / 365) > 2), "2+", ((TODAY() - E35) / 365) ) -> 0.34520548 | AU35: =IF( OR( (Member_Status!$AP34<-240), (Member_Status!$AS34<>0), (Member_Status!$AR34<58%) ), "No", "Yes") -> No | AV35: =IF( OR(Member_Status!$AQ35<>"Yes",AU35 <>"Yes" ), "No", "Yes" ) -> No | AW35: =IF( AND(AX35<149, OR(Member_Status!$AQ35<>"Yes", AT35<2 ) ), "No", "Yes" ) -> Yes | AX35: 154 | BA35: 120
A36: Member | B36: Mrs. | C36: Ngene | D36: Abigail Enaibre | E36: 46113 | F36: 3132587910 | O36: 190 | AF36: =SUM(H36:AE36) -> 190 | AG36: =(AF36 - (20* (MONTH(TODAY()) ))) -> 30 | AH36: - | AI36: - | AJ36: - | AK36: - | AL36: - | AM36: - | AN36: - | AO36: - | AP36: =SUM(AG36:AO36) -> 30 | AQ36: =IF((Member_Status!$AP36<-240), "No", "Yes") -> Yes | AR36: =COUNTIF(Member_Status!$H35:$AE35, "Present") / (MONTH(TODAY()-23 )) -> 0 | AS36: ='Bereavment Collection'!C35 -> 0 | AT36: =IF( (((TODAY() - E36) / 365) > 2), "2+", ((TODAY() - E36) / 365) ) -> 0.34520548 | AU36: =IF( OR( (Member_Status!$AP35<-240), (Member_Status!$AS35<>0), (Member_Status!$AR35<58%) ), "No", "Yes") -> No | AV36: =IF( OR(Member_Status!$AQ36<>"Yes",AU36 <>"Yes" ), "No", "Yes" ) -> No | AW36: =IF( AND(AX36<149, OR(Member_Status!$AQ36<>"Yes", AT36<2 ) ), "No", "Yes" ) -> Yes | AX36: 154 | BA36: 120
A37: Member | B37: Mrs. | C37: Obi | D37: Rebecca | E37: 45658 | F37: 3138296855 | J37: Present | L37: Present | M37: 100 | P37: Present | U37: 140 | AF37: =SUM(H37:AE37) -> 240 | AG37: =(AF37 - (20* (MONTH(TODAY()) ))) -> 80 | AH37: 0 | AI37: 0 | AJ37: 0 | AK37: -70 | AL37: 50 | AM37: 80 | AN37: - | AO37: 0 | AP37: =SUM(AG37:AO37) -> 140 | AQ37: =IF((Member_Status!$AP37<-240), "No", "Yes") -> Yes | AR37: =COUNTIF(Member_Status!$H75:$AE75, "Present") / (MONTH(TODAY()-23 )) -> 0.57142857 | AS37: ='Bereavment Collection'!C72 -> 0 | AT37: =IF( (((TODAY() - E37) / 365) > 2), "2+", ((TODAY() - E37) / 365) ) -> 1.5917808 | AU37: =IF( OR( (Member_Status!$AP75<-240), (Member_Status!$AS75<>0), (Member_Status!$AR75<58%) ), "No", "Yes") -> No | AV37: =IF( OR(Member_Status!$AQ37<>"Yes",AU37 <>"Yes" ), "No", "Yes" ) -> No | AW37: =IF( AND(AX37<149, OR(Member_Status!$AQ37<>"Yes", AT37<2 ) ), "No", "Yes" ) -> Yes | AX37: 153 | AY37: m | AZ37: 1 | BA37: 120 | BB37: 46082 | BD37: 20 | BG37: 20
A38: Member | B38: Mrs. | C38: Odjugo | D38: Emuobonuvie | E38: 36892 | F38: 7346297746 | G38: emuoboq@gmail.com | H38: Present | J38: Present | L38: Present | P38: Present | AF38: =SUM(H38:AE38) -> 0 | AG38: =(AF38 - (20* (MONTH(TODAY()) ))) -> -160 | AH38: -140 | AI38: 180 | AJ38: -20 | AK38: 20 | AL38: -120 | AM38: 200 | AN38: - | AO38: - | AP38: =SUM(AG38:AO38) -> -40 | AQ38: =IF((Member_Status!$AP38<-240), "No", "Yes") -> Yes | AR38: =COUNTIF(Member_Status!$H34:$AE34, "Present") / (MONTH(TODAY()-23 )) -> 0.14285714 | AS38: ='Bereavment Collection'!C35 -> 0 | AT38: =IF( (((TODAY() - E38) / 365) > 2), "2+", ((TODAY() - E38) / 365) ) -> 2+ | AU38: =IF( OR( (Member_Status!$AP34<-240), (Member_Status!$AS34<>0), (Member_Status!$AR34<58%) ), "No", "Yes") -> No | AV38: =IF( OR(Member_Status!$AQ38<>"Yes",AU38 <>"Yes" ), "No", "Yes" ) -> No | AW38: =IF( AND(AX38<149, OR(Member_Status!$AQ38<>"Yes", AT38<2 ) ), "No", "Yes" ) -> Yes | AY38: f | AZ38: 1 | BA38: 120 | BB38: 46113
A39: Member | B39: Mrs. | C39: Odjugo | D39: Julie | E39: 43617 | F39: 3136758795 | G39: =VLOOKUP(Member_Status!$D34,contacts!A:G,3,FALSE) -> emoubo4real@yahoo.com | J39: Present | AF39: =SUM(H39:AE39) -> 0 | AG39: =(AF39 - (20* (MONTH(TODAY()) ))) -> -160 | AH39: -240 | AI39: 240 | AJ39: 0 | AK39: -240 | AL39: -120 | AM39: 0 | AN39: - | AO39: - | AP39: =SUM(AG39:AO39) -> -520 | AQ39: =IF((Member_Status!$AP39<-240), "No", "Yes") -> No | AR39: =COUNTIF(Member_Status!$H38:$AE38, "Present") / (MONTH(TODAY()-23 )) -> 0.57142857 | AS39: ='Bereavment Collection'!C37 -> -200 | AT39: =IF( (((TODAY() - E39) / 365) > 2), "2+", ((TODAY() - E39) / 365) ) -> 2+ | AU39: =IF( OR( (Member_Status!$AP38<-240), (Member_Status!$AS38<>0), (Member_Status!$AR38<58%) ), "No", "Yes") -> No | AV39: =IF( OR(Member_Status!$AQ39<>"Yes",AU39 <>"Yes" ), "No", "Yes" ) -> No | AW39: =IF( AND(AX39<149, OR(Member_Status!$AQ39<>"Yes", AT39<2 ) ), "No", "Yes" ) -> No | AY39: f | BB39: 46113
A40: Member | B40: Papa | C40: Odjugo | D40: Joeseph Efe | E40: 36892 | F40: 7346297746 | G40: =VLOOKUP(Member_Status!$D38,contacts!A:G,3,FALSE) -> #N/A | AF40: =SUM(H40:AE40) -> 0 | AG40: =(SUM(H40:AE40) - (20* (MONTH(TODAY()) ))) -> -160 | AH40: -120 | AI40: -120 | AJ40: 0 | AK40: 0 | AL40: 0 | AM40: 0 | AN40: 0 | AO40: -60 | AP40: =SUM(AG40:AO40) -> -460 | AQ40: =IF((Member_Status!$AP40<-120), "No", "Yes") -> No | AR40: =COUNTIF(Member_Status!$H37:$AE37, "Present") / (MONTH(TODAY()-23 )) -> 0.42857143 | AS40: ='Bereavment Collection'!C36 -> -150 | AT40: =IF( (((TODAY() - E40) / 365) > 2), "2+", ((TODAY() - E40) / 365) ) -> 2+ | AU40: =IF( OR( (Member_Status!$AP37<-240), (Member_Status!$AS37<>0), (Member_Status!$AR37<58%) ), "No", "Yes") -> No | AV40: =IF( OR(Member_Status!$AQ40<>"Yes",AU40 <>"Yes" ), "No", "Yes" ) -> No | AW40: =IF( AND(AX40<149, OR(Member_Status!$AQ40<>"Yes", AT40<2 ) ), "No", "Yes" ) -> No | AY40: m | BB40: elder
...

Sheet Bereavment Collection
A1: Last | B1: First | C1: Owes | D1: Pauline's Wedding!! | E1: Ese's Wedding!! | F1: Alawaru's Bereavement | G1: Onosode Bereavement | H1: Julie Warrence Bereavment | I1: Paul Warrence Bereavment | J1: Toweh Bereavment | K1: benefactor7
A2: Abada | B2: Evi | C2: =IF(SUM(D2:G2)>0, 0, (SUM(D2:G2))) -> 0 | D2: 0 | E2: 0 | F2: 0 | G2: 0 | H2: 0 | I2: 0 | J2: 0
A3: Abada | B3: Otuke | C3: =IF(SUM(D3:G3)>0, 0, (SUM(D3:G3))) -> 0 | D3: 0 | E3: 0 | F3: 0 | G3: 0 | H3: 0 | I3: 0 | J3: 0
A4: Agbara | B4: Onome | C4: =IF(SUM(D4:G4)>0, 0, (SUM(D4:G4))) -> 0 | D4: 0 | E4: 0 | F4: 0 | G4: 0 | H4: 0 | I4: 0 | J4: 0
A5: Akaba | B5: Maureen | C5: =IF(SUM(D5:G5)>0, 0, (SUM(D5:G5))) -> 0 | D5: 0 | E5: 0 | F5: 0 | G5: 0 | H5: 0 | I5: 50 | J5: 0
A6: Akaba | B6: Monday | C6: =IF(SUM(D6:G6)>0, 0, (SUM(D6:G6))) -> 0 | D6: 25 | E6: 25 | F6: 0 | G6: 0 | H6: 0 | I6: 50 | J6: 0
A7: Akporee | B7: Emudiaga | H7: 0 | I7: 0 | J7: 0
A8: Alawuru | B8: Precious | C8: =IF(SUM(D8:G8)>0, 0, (SUM(D8:G8))) -> 0 | D8: 50 | E8: 50 | F8: 0 | G8: 0 | H8: 0 | I8: 50 | J8: 0
A9: Amegee | B9: Ruona | C9: =IF(SUM(D9:G9)>0, 0, (SUM(D9:G9))) -> -50 | D9: 0 | E9: 0 | F9: -50 | G9: 0 | H9: 0 | I9: 50 | J9: 50
A10: Asidi | B10: Fejiro | H10: 0 | I10: 0 | J10: 0
A11: Atori | B11: Victoria | C11: =IF(SUM(D11:G11)>0, 0, (SUM(D11:G11))) -> -200 | D11: 0 | E11: 0 | F11: -50 | G11: -150 | H11: 0 | I11: 0 | J11: 50
A12: Chiefredo | B12: Merit | C12: =IF(SUM(D12:G12)>0, 0, (SUM(D12:G12))) -> 0 | D12: 0 | E12: 0 | F12: 0 | G12: 0 | H12: 0 | I12: 50 | J12: 50
A13: Dilworth | B13: Aghogho | C13: =IF(SUM(D13:G13)>0, 0, (SUM(D13:G13))) -> 0 | D13: 0 | E13: 0 | F13: 0 | G13: 0 | H13: 0 | I13: 50 | J13: 50
A14: Eghwofobe | B14: Ngozi | C14: =IF(SUM(D14:G14)>0, 0, (SUM(D14:G14))) -> -50 | D14: 0 | E14: 0 | F14: -50 | G14: 0 | H14: 0 | I14: 50 | J14: 0
A15: Ejafiavwo | B15: Florence | C15: =IF(SUM(D15:G15)>0, 0, (SUM(D15:G15))) -> -50 | D15: 0 | E15: 0 | F15: -50 | G15: 0 | H15: 0 | I15: 0 | J15: 0
A16: Ejafiavwo | B16: Robinson | C16: =IF(SUM(D16:G16)>0, 0, (SUM(D16:G16))) -> 0 | D16: 25 | E16: 25 | F16: -50 | G16: 0 | H16: 0 | I16: 0 | J16: 0
A17: Emadamerho | B17: Belief | C17: =IF(SUM(D17:G17)>0, 0, (SUM(D17:G17))) -> 0 | D17: 50 | E17: 50 | F17: -50 | G17: 0 | H17: 0 | I17: 0 | J17: 50
A18: Emadamerho | B18: Krishawn | C18: =IF(SUM(D18:G18)>0, 0, (SUM(D18:G18))) -> -50 | D18: 0 | E18: 0 | F18: -50 | G18: 0 | H18: 0 | I18: 0 | J18: 50
A19: Emekpe | B19: Enovwo | C19: =IF(SUM(D19:G19)>0, 0, (SUM(D19:G19))) -> 0 | D19: 100 | E19: - | F19: 0 | G19: 0 | H19: 0 | I19: 50 | J19: 50
A20: Esegine | B20: Johnson | C20: =IF(SUM(D20:G20)>0, 0, (SUM(D20:G20))) -> -50 | D20: 0 | E20: 0 | F20: -50 | G20: 0 | H20: Elder exempt | I20: Elder exempt | J20: Elder exempt
A21: Esegine | B21: Rebecca | C21: =IF(SUM(D21:G21)>0, 0, (SUM(D21:G21))) -> -50 | D21: 0 | E21: 0 | F21: -50 | G21: 0 | H21: Elder exempt | I21: Elder exempt | J21: Elder exempt
A22: Evwaraye | B22: Joke | C22: =IF(SUM(D22:G22)>0, 0, (SUM(D22:G22))) -> 0 | D22: 0 | E22: 0 | F22: 0 | G22: 0 | H22: 0 | I22: 50 | J22: 50
A23: Evwaraye | B23: Otivie | C23: =IF(SUM(D23:G23)>0, 0, (SUM(D23:G23))) -> 0 | D23: 0 | E23: 0 | F23: 0 | G23: 0 | H23: 0 | I23: 50 | J23: 50
A24: Emetiyoma | B24: Kwesi | C24: =IF(SUM(D24:G24)>0, 0, (SUM(D24:G24))) -> 0 | D24: - | E24: - | F24: - | G24: 0 | H24: 0 | I24: 50 | J24: 50
A25: Eruoto | B25: Jude | C25: =IF(SUM(D25:G25)>0, 0, (SUM(D25:G25))) -> 0 | D25: - | E25: - | F25: - | G25: 0 | H25: 0 | I25: 0 | J25: 0
A26: George | B26: Lovette | C26: =IF(SUM(D26:G26)>0, 0, (SUM(D26:G26))) -> 0 | D26: 0 | E26: 0 | F26: 0 | G26: 0 | H26: 0 | I26: 0 | J26: 0
A27: Ighofose | B27: Ochuko | C27: =IF(SUM(D27:G27)>0, 0, (SUM(D27:G27))) -> 0 | D27: 0 | E27: 0 | F27: 0 | G27: 0 | H27: 0 | I27: 50 | J27: 0
A28: Ighofose | B28: Sarah | C28: =IF(SUM(D28:G28)>0, 0, (SUM(D28:G28))) -> 0 | D28: 0 | E28: 0 | F28: 0 | G28: 0 | H28: 0 | I28: 50 | J28: 0
A29: Ikaji | B29: Theresa | C29: =IF(SUM(D29:G29)>0, 0, (SUM(D29:G29))) -> -200 | D29: 0 | E29: 0 | F29: -50 | G29: -150 | H29: 0 | I29: 0 | J29: 0
A30: Isiorho | B30: Kensinde | C30: =IF(SUM(D30:G30)>0, 0, (SUM(D30:G30))) -> -50 | D30: 0 | E30: 0 | F30: -50 | G30: 0 | H30: 0 | I30: 50 | J30: 0
A31: Minor | B31: Annete-Onoriode | C31: =IF(SUM(D31:G31)>0, 0, (SUM(D31:G31))) -> 0 | D31: 50 | E31: 50 | F31: 0 | G31: 0 | H31: 0 | I31: 0 | J31: 50
A32: Nana | B32: Edewor | C32: =IF(SUM(D32:G32)>0, 0, (SUM(D32:G32))) -> 0 | D32: 0 | E32: 0 | F32: 0 | G32: 0 | H32: 0 | I32: 0 | J32: 50
A33: Nana | B33: Tessy | C33: =IF(SUM(D33:G33)>0, 0, (SUM(D33:G33))) -> 0 | D33: 0 | E33: 0 | F33: 0 | G33: 0 | H33: 0 | I33: 0 | J33: 50
A34: Obi | B34: Rebecca | C34: =IF(SUM(D34:G34)>0, 0, (SUM(D34:G34))) -> 0 | D34: 0 | E34: 0 | F34: 0 | G34: 0 | H34: 0 | I34: 50 | J34: 50
A35: Odjugo | B35: Emuobonuvie | C35: =IF(SUM(D35:G35)>0, 0, (SUM(D35:G35))) -> 0 | D35: 0 | E35: 0 | F35: 50 | G35: 0 | H35: 0 | I35: 0 | J35: 0
A36: Odjugo | B36: Joeseph Efe | C36: =IF(SUM(D36:G36)>0, 0, (SUM(D36:G36))) -> -150 | D36: 0 | E36: 0 | F36: - | G36: -150 | H36: Elder exempt | I36: Elder exempt | J36: Elder exempt
A37: Odjugo | B37: Julie | C37: =IF(SUM(D37:G37)>0, 0, (SUM(D37:G37))) -> -200 | D37: 0 | E37: 0 | F37: -50 | G37: -150 | H37: 0 | I37: 0 | J37: 0
A38: Odjugo | B38: Ochuko | C38: =IF(SUM(D38:G38)>0, 0, (SUM(D38:G38))) -> -200 | D38: 0 | E38: 0 | F38: -50 | G38: -150 | H38: 0 | I38: 0 | J38: 0
A39: Odjugo | B39: Vera | H39: 0 | I39: 0 | J39: 0
A40: Oghoufo | B40: Anthonia | C40: =IF(SUM(D40:G40)>0, 0, (SUM(D40:G40))) -> 0 | D40: 0 | E40: 0 | F40: 0 | G40: 0 | H40: 0 | I40: 50 | J40: 0
...

Sheet contacts
A1: First Name | B1: Last Name | C1: Email 1 | D1: Email 1 lists | E1: Email 2 | F1: Phone 1 | G1: Address 1
A2: Beauty | B2: Ovbije-Onomake | C2: beautysinternationalmktplace@hotmail.com | D2: UPUMI Members
A3: Jeff | B3: Ngene | C3: jeffngene701@gmail.com | D3: UPUMI Members
A7: Ovieh | B7: Onomake | C7: oviehonomake@aol.com | D7: UPUMI Members
A8: abigail | C8: abigaili4848@gmail.com | D8: UPUMI Members
A10: Abigail Enaibre | B10: Ngene | C10: abigailenaibre@gmail.com | D10: UPUMI Members
A11: Adefolake | B11: Bakare | C11: afollybbz@gmail.com | D11: UPUMI Members
A18: Akpesiri-Onoriode | B18: onosode | C18: oonosode@aol.com | D18: UPUMI Members | E18: mgr32290@bp.com | F18: (248) 318-4092 | G18: 17423 Glenmore St, Redford, mi
A19: Alex | B19: Ughwanogho | C19: oghogho@aol.com | D19: UPUMI Members
A20: Anneth | B20: Evwaraye | C20: annethevwaraye@yahoo.com | D20: UPUMI Members
A21: Annete-Onoriode | B21: Minor | C21: antoolivia@yahoo.com | D21: UPUMI Members
A32: Aruegodore | B32: Oyibororho | C32: ovwa22@aol.com | D32: UPUMI Members
A53: Belief | B53: Emadamero | C53: belief80@yahoo.com | D53: UPUMI Members
A59: Bonifcae | B59: Tubie | C59: user672848@aol.com | D59: UPUMI Members
A63: Bruno | B63: Okere | C63: b_okere@yahoo.com | D63: UPUMI Members | F63: (586) 222-3482
A69: chief Dr. | B69: Imarhiagbe | C69: chief.imarah@gmail.com | D69: UPUMI Members
A70: Chris | B70: Akus | C70: chris.akus@yahoo.com | D70: UPUMI Members
A71: Dogood Efenogo | C71: efenogo@yahoo.com | D71: UPUMI Members
A78: Benson | B78: Oghoufo | C78: toben4@yahoo.com | D78: UPUMI Members
A79: Eguono | B79: Onokpikini | C79: eguonochantex@gmail.com | D79: UPUMI Members | F79: (517) 331-7291
A160: Emuobosan | B160: Ojaruega | C160: mobo1777@gmail.com | D160: UPUMI Members | F160: (248) 636-6884
A162: Eneta | B162: Uwedjojewe | C162: euwedjo@hotmail.com | D162: UPUMI Members
A163: Enovwo | B163: Emekpe | C163: enovwo2@yahoo.com | D163: UPUMI Members | F163: (248) 885-2808 | G163: 13805 pond bluff, vanburen township, MI, 48111
A271: Ese | B271: Wanogho | C271: praiseway1999@gmail.com | D271: UPUMI Members | E271: sonianwoke@gmail.com | F271: 313-622-3628
A274: Ese | C274: america4ese@gmail.com | D274: UPUMI Members
A298: esonetmedical@peoplepc.com | C298: esonetmedical@peoplepc.com | D298: UPUMI Members
A307: Etaroghene | B307: Emurashe | C307: eemurashe@yahoo.com | D307: UPUMI Members
A308: Friday | B308: Megabje | C308: megbaje8080@yahoo.com | D308: UPUMI Members
A337: Gift | B337: Agege | C337: nefioms76@yahoo.com | D337: UPUMI Members
A340: Gladys | B340: Wanogho | C340: gladyswanogho@icloud.com | D340: UPUMI Members | F340: (248) 943-5989 | G340: 28007 Tavistock Trl, Southfield, MI, United State
A363: goddey | C363: goddey@aol.com | D363: UPUMI Members
A364: Godfrey | B364: Wanogho | C364: etareri@yahoo.com | D364: UPUMI Members | F364: (248) 943-5811
A366: Gregory | B366: Dedeku | C366: gregory.dedeku@yahoo.com | D366: UPUMI Members
A367: Jones | B367: Oleita | C367: oleitaj@gmail.com | D367: UPUMI Members
A368: Kevin | B368: Onokpikini | C368: kelvinetaro@yahoo.com | D368: UPUMI Members
A369: Kevwe | B369: Akpore | C369: kevwe_kk@yahoo.com | D369: UPUMI Members
A373: Kwesi | B373: Emretiyoma | C373: meanvipro@yahoo.com | D373: UPUMI Members
A374: Monday | B374: Akaba | C374: mondaya@comcast.net | D374: UPUMI Members
A377: Mrs. Bose | B377: Djere | C377: love4jenni@yahoo.com | D377: UPUMI Members
A378: Mrs. Queen | B378: Toweh | C378: onajitetoweh@att.net | D378: UPUMI Members | E378: onajitetoweh@attend.net
...

Sheet Xmas-GiftCards
A1: First | B1: Last | C1: Age 2020 | D1: Age 2025 | E1: Home Address | F1: Phone | G1: Email | H1: Text | I1: Facebook | J1: Website | K1: Birthday | L1: Good Standing
A2: Xmas | B2: GiftCard | D2: - | E2: Total | H2: =SUM(H3:H58) -> 1146.14
A3: Xmas | B3: GreetingCards | H3: =3.98+7.98+7.98+1.2 -> 21.14
A4: Extra Cards | B4: BackUp 11 | H4: =11*25 -> 275
A5: Julissa | B5: Eruoto | H5: 25
A6: Ovie | B6: Abada | H6: 25
A7: Oke | B7: Abada | H7: 25
A8: Emuobosa David | B8: Okagbare | C8: 10 | D8: 14 | E8: 27139 Sutherland street Southfield MI 48076 | H8: 25 | L8: =Member_Status!AQ45 -> No
A9: Ogheneruno Eva | B9: Okagbare | C9: 9 | D9: 13 | E9: 27139 Sutherland street Southfield MI 48076 | H9: 25 | L9: =Member_Status!AQ45 -> No
A10: Oghenefjiro | B10: Okagbare | C10: 2 | D10: 6 | E10: 27139 Sutherland street Southfield MI 48076 | H10: 25 | L10: =Member_Status!AQ46 -> Yes
A11: Yoma | B11: Onosode | C11: 9 | D11: 13 | E11: 7011 Clampton ct. Canton MI 48188 | H11: 25 | L11: =Member_Status!AQ55 -> Yes
A12: Ejiro | B12: Onosode | C12: 5 | D12: 9 | E12: 7011 Clampton ct. Canton MI 48188 | H12: 25 | L12: =Member_Status!AQ55 -> Yes
A13: Ovie | B13: Emekpe | C13: 14 | D13: 18 | E13: 13805 Pond bluff Dr, Belleville MI 48111 | H13: 25 | L13: =Member_Status!AQ18 -> No
A14: Ogaga | B14: Emekpe | C14: 3 | D14: 7 | E14: 13805 Pond bluff Dr, Belleville MI 48111 | H14: 25 | K14: 43436 | L14: =Member_Status!AQ21 -> Yes
A15: Ewoma | B15: Onosode | C15: 11 | D15: 15 | E15: 14269 Sunset st, Livonia, MI 48154 | H15: 25 | L15: =Member_Status!AQ56 -> No
A16: Rute | B16: Onosode | C16: 8 | D16: 12 | E16: 14269 Sunset st, Livonia, MI 48154 | H16: 25 | L16: =Member_Status!AQ55 -> Yes
A17: Brume | B17: Akaba | C17: 12 | D17: 16 | E17: 30113 Sparkleberry dr. Southfield MI, 48076 | H17: 25 | L17: =Member_Status!AQ4 -> Yes
A18: Ejomafuwve | B18: Okagbare | C18: 9 | D18: 13 | E18: 2163 woodbine dr Canton, MI 48188 | H18: 25 | L18: =Member_Status!AQ46 -> Yes
A19: Isabella | B19: Ojaruega | C19: 8 | D19: 12 | E19: 58 Leanee lane Pontiac MI, 48340 | H19: 25 | L19: =Member_Status!AQ43 -> Yes
A20: Geo | B20: Ojaruega | C20: 3 | D20: 7 | E20: 58 Leanee lane Pontiac MI, 48340 | H20: 25 | L20: =Member_Status!AQ43 -> Yes
A21: Oghenevomero | B21: Odjugo | C21: 9 | D21: 13 | E21: 17049 buckeye ct Ramulus, MI 48174 | H21: 25 | L21: =Member_Status!AQ37 -> Yes
A22: Efe | B22: Emadamerho | C22: 14 | D22: 18 | E22: 3371 south John hix road Wayne, MI 48184 | H22: 25 | L22: =Member_Status!AQ17 -> No
A23: Ordame | B23: Emadamerho | C23: 9 | D23: 13 | E23: 3371 south John hix road Wayne, MI 48184 | H23: 25 | L23: =Member_Status!AQ17 -> No
A24: Orodje | B24: Emadamerho | C24: 8 | D24: 12 | E24: 3371 south John hix road Wayne, MI 48184 | H24: 25 | L24: =Member_Status!AQ17 -> No
A25: Howard | B25: Dilworth | C25: 8 | D25: 12 | E25: 2545 Belvidere st Detroit, MI 48214 | H25: 25 | L25: =Member_Status!AQ13 -> No
A26: Dorian | B26: Dilworth | C26: 2 | D26: 6 | E26: 2545 Belvidere st Detroit, MI 48214 | H26: 25 | L26: =Member_Status!AQ13 -> No
A27: John | B27: Dilworth | C27: 6 | D27: 10 | E27: 2545 Belvidere st Detroit, MI 48214 | H27: 25 | L27: =Member_Status!AQ13 -> No
A28: Jac | B28: Amegee | C28: 5 | D28: 9 | E28: 23475 Long Point Way #308 Novi, MI 48375 | H28: 25 | L28: =Member_Status!AQ10 -> Yes
A29: Isreal | B29: Okere | C29: 13 | D29: 17 | E29: 13609 Geoffry drive Warren MI 480889 | H29: 25 | L29: =Member_Status!AQ48 -> Yes
A30: Mercy | B30: Okere | C30: 12 | D30: 16 | E30: 13609 Geoffry drive Warren MI 480889 | H30: 25 | L30: =Member_Status!AQ48 -> Yes
A31: benjamin | B31: Okere | C31: 10 | D31: 14 | E31: 13609 Geoffry drive Warren MI 480889 | H31: 25 | L31: =Member_Status!AQ48 -> Yes
A32: Ovie | B32: Etaroghene | C32: 11 | D32: 15 | E32: 11037 Lochgreen dr. Lansing MI 48917 | H32: 25 | L32: =Member_Status!AQ52 -> No
A33: Erhuvwun | B33: Etaroghene | C33: 9 | D33: 13 | E33: 11037 Lochgreen dr. Lansing MI 48917 | H33: 25 | L33: =Member_Status!AQ52 -> No
A34: Makeshe | B34: Etaroghene | C34: 7 | D34: 11 | E34: 11037 Lochgreen dr. Lansing MI 48917 | H34: 25 | L34: =Member_Status!AQ52 -> No
A35: Ivie | B35: Etaroghene | C35: 5 | D35: 9 | E35: 11037 Lochgreen dr. Lansing MI 48917 | H35: 25 | L35: =Member_Status!AQ52 -> No
A36: Efe | B36: Etaroghene | C36: 2 | D36: 6 | E36: 11037 Lochgreen dr. Lansing MI 48917 | H36: 25 | L36: =Member_Status!AQ52 -> No
A37: Odafe | B37: Okagbare | C37: 14 | D37: 18 | E37: 1058 villa court north, Walled Lake MI 48390 | H37: 25 | L37: =Member_Status!AQ44 -> Yes
A38: Etaroghene | B38: Okagbare | C38: 10 | D38: 14 | E38: 1058 villa court north, Walled Lake MI 48390 | H38: 25 | L38: =Member_Status!AQ44 -> Yes
A39: Nyerhovwo | B39: Onosode | C39: 17 | D39: 21 | E39: 14269 Sunset st, Livonia, MI 48154 | H39: 0 | L39: Aged Out
A40: Rachel | B40: Akaba | C40: 17 | D40: 21 | E40: 30113 Sparkleberry dr. Southfield MI, 48076 | H40: 0 | L40: Aged Out
...

Sheet Raffle
A1: Ticket# | B1: Title | C1: Last | D1: First
A2: =RANDBETWEEN(1000000, 9999999) -> 8771282 | B2: Mrs. | C2: Evwaraye | D2: Laura Adejoke
A3: =RANDBETWEEN(1000000, 9999999) -> 1853945 | B3: Mrs. | C3: Abada | D3: Evi
A4: =RANDBETWEEN(1000000, 9999999) -> 2280906 | B4: Mr. | C4: Abada | D4: Otuke
A5: =RANDBETWEEN(1000000, 9999999) -> 1312731 | B5: Mr. | C5: Agbara | D5: Onome
A6: =RANDBETWEEN(1000000, 9999999) -> 5115776 | B6: Mrs. | C6: Akaba | D6: Maureen
A7: =RANDBETWEEN(1000000, 9999999) -> 9948127 | B7: Mr. | C7: Akaba | D7: Monday
A8: =RANDBETWEEN(1000000, 9999999) -> 5303995 | B8: Pastor | C8: Alawuru | D8: Precious
A9: =RANDBETWEEN(1000000, 9999999) -> 1781978 | B9: Mrs. | C9: Amegee | D9: Ruona
A10: =RANDBETWEEN(1000000, 9999999) -> 2865863 | B10: Ms. | C10: Asidi | D10: Fejiro
A11: =RANDBETWEEN(1000000, 9999999) -> 3309964 | B11: Mrs. | C11: Atori | D11: Victoria
A12: =RANDBETWEEN(1000000, 9999999) -> 7115478 | B12: Mrs. | C12: Chiefrego | D12: Merit
A13: =RANDBETWEEN(1000000, 9999999) -> 3706107 | B13: Mrs. | C13: Dilworth | D13: Aghogho
... A621: =RANDBETWEEN(1000000, 9999999) -> 4128443 | B621: Mr. | C621: Warrence | D621: Paul
